Workbook

Sheet README
A1: Training Log — 11-Week Hypertrophy Block
A2: Block: 2026-04-27 → 2026-07-12 • User: Leonardo • Last rebuild driven by scripts/build_log.py
A4: TABS
A5: • Charts — KPI snapshot (live) + 6 progression charts. Open this first.
A6: • Lifting Log — every working set. Edit here to add new sessions.
A7: • Running Log — every run. Edit here to add runs.
A8: • Body Metrics — daily BW + weekly tape measurements.
A9: • Personal Records — auto best lifts (recomputes on open).
A10: • Weekly Summary — auto weekly volume / RPE / runs / BW.
A11: • Progression Data — weekly best e1RM per priority lift (chart source).
A12: • Reference — HR / pace zones, schedule, RPE table.
A14: HOW IT WORKS
... A20: RPE 6 = 4 RIR • 7 = 3 RIR • 8 = 2 RIR (most of block) • 9 = 1 RIR (peak) • 10 = failure (isolation only).

Sheet Charts
B1: Block 1 — Visual Progression
B2: Charts auto-update from Lifting Log / Running Log / Body Metrics. KPI cells live below.
B4: KPI snapshot
B5: Sessions logged | C5: =SUMPRODUCT(IFERROR(('Lifting Log'!E2:E801=1)/COUNTIFS('Lifting Log'!A:A,'Lifting Log'!A2:A801,'Lifting Log'!E:E,1),0))
B6: Total working sets | C6: =COUNTA('Lifting Log'!E2:E801)
B7: Total volume (kg) | C7: =SUM('Lifting Log'!I2:I801)
B8: Avg RPE (all sets) | C8: =IFERROR(AVERAGE('Lifting Log'!H2:H801),"")
B9: Bench best e1RM (kg) | C9: =IF(COUNTIF('Lifting Log'!D:D,"Bench Press")=0,"",SUMPRODUCT(MAX(('Lifting Log'!D2:D801="Bench Press")*IFERROR('Lifting Log'!J2:J801*1,0))))
B10: Squat best e1RM (kg) | C10: =IF(COUNTIF('Lifting Log'!D:D,"Back Squat")=0,"",SUMPRODUCT(MAX(('Lifting Log'!D2:D801="Back Squat")*IFERROR('Lifting Log'!J2:J801*1,0))))
B11: OHP best e1RM (kg) | C11: =IF(COUNTIF('Lifting Log'!D:D,"Overhead Press")=0,"",SUMPRODUCT(MAX(('Lifting Log'!D2:D801="Overhead Press")*IFERROR('Lifting Log'!J2:J801*1,0))))
B12: Latest BW (kg) | C12: =IFERROR(LOOKUP(2,1/('Body Metrics'!C2:C200<>""),'Body Metrics'!C2:C200),"")
B13: BW Δ vs Wk 1 (kg) | C13: =IFERROR(LOOKUP(2,1/('Body Metrics'!C2:C200<>""),'Body Metrics'!C2:C200)-INDEX('Body Metrics'!C:C,MATCH(TRUE,INDEX('Body Metrics'!C2:C200<>"",0),0)+1),"")
B14: Total run km | C14: =SUM('Running Log'!C2:C151)

Sheet Lifting Log
A1: Date | B1: Week | C1: Day | D1: Exercise | E1: Set # | F1: Reps | G1: Weight (kg) | H1: RPE | I1: Volume (kg) | J1: e1RM (kg) | K1: Notes
A2: 46146 | B2: =IF(A2="","",IFERROR(INT((A2-DATE(2026,4,27))/7)+1,"")) | C2: Upper A | D2: Bench Press | E2: 1 | F2: 7 | G2: 32.5 | H2: 7 | I2: =IF(OR(F2="",G2=""),"",F2*G2) | J2: =IF(OR(F2="",G2=""),"",ROUND(G2*(1+F2/30),1))
A3: 46146 | B3: =IF(A3="","",IFERROR(INT((A3-DATE(2026,4,27))/7)+1,"")) | C3: Upper A | D3: Bench Press | E3: 2 | F3: 7 | G3: 32.5 | H3: 8 | I3: =IF(OR(F3="",G3=""),"",F3*G3) | J3: =IF(OR(F3="",G3=""),"",ROUND(G3*(1+F3/30),1))
A4: 46146 | B4: =IF(A4="","",IFERROR(INT((A4-DATE(2026,4,27))/7)+1,"")) | C4: Upper A | D4: Bench Press | E4: 3 | F4: 7 | G4: 32.5 | H4: 8 | I4: =IF(OR(F4="",G4=""),"",F4*G4) | J4: =IF(OR(F4="",G4=""),"",ROUND(G4*(1+F4/30),1))
A5: 46146 | B5: =IF(A5="","",IFERROR(INT((A5-DATE(2026,4,27))/7)+1,"")) | C5: Upper A | D5: Bench Press | E5: 4 | F5: 7 | G5: 32.5 | H5: 8 | I5: =IF(OR(F5="",G5=""),"",F5*G5) | J5: =IF(OR(F5="",G5=""),"",ROUND(G5*(1+F5/30),1)) | K5: bump 35 next
A6: 46146 | B6: =IF(A6="","",IFERROR(INT((A6-DATE(2026,4,27))/7)+1,"")) | C6: Upper A | D6: Barbell Row | E6: 1 | F6: 7 | G6: 32.5 | H6: 8 | I6: =IF(OR(F6="",G6=""),"",F6*G6) | J6: =IF(OR(F6="",G6=""),"",ROUND(G6*(1+F6/30),1))
A7: 46146 | B7: =IF(A7="","",IFERROR(INT((A7-DATE(2026,4,27))/7)+1,"")) | C7: Upper A | D7: Barbell Row | E7: 2 | F7: 7 | G7: 32.5 | H7: 8 | I7: =IF(OR(F7="",G7=""),"",F7*G7) | J7: =IF(OR(F7="",G7=""),"",ROUND(G7*(1+F7/30),1))
A8: 46146 | B8: =IF(A8="","",IFERROR(INT((A8-DATE(2026,4,27))/7)+1,"")) | C8: Upper A | D8: Barbell Row | E8: 3 | F8: 7 | G8: 32.5 | H8: 8 | I8: =IF(OR(F8="",G8=""),"",F8*G8) | J8: =IF(OR(F8="",G8=""),"",ROUND(G8*(1+F8/30),1))
A9: 46146 | B9: =IF(A9="","",IFERROR(INT((A9-DATE(2026,4,27))/7)+1,"")) | C9: Upper A | D9: Barbell Row | E9: 4 | F9: 7 | G9: 32.5 | H9: 8 | I9: =IF(OR(F9="",G9=""),"",F9*G9) | J9: =IF(OR(F9="",G9=""),"",ROUND(G9*(1+F9/30),1)) | K9: bump 35 next
A10: 46146 | B10: =IF(A10="","",IFERROR(INT((A10-DATE(2026,4,27))/7)+1,"")) | C10: Upper A | D10: Incline DB Press | E10: 1 | F10: 10 | G10: 12 | H10: 8 | I10: =IF(OR(F10="",G10=""),"",F10*G10) | J10: =IF(OR(F10="",G10=""),"",ROUND(G10*(1+F10/30),1))
A11: 46146 | B11: =IF(A11="","",IFERROR(INT((A11-DATE(2026,4,27))/7)+1,"")) | C11: Upper A | D11: Incline DB Press | E11: 2 | F11: 9 | G11: 12 | H11: 8 | I11: =IF(OR(F11="",G11=""),"",F11*G11) | J11: =IF(OR(F11="",G11=""),"",ROUND(G11*(1+F11/30),1))
A12: 46146 | B12: =IF(A12="","",IFERROR(INT((A12-DATE(2026,4,27))/7)+1,"")) | C12: Upper A | D12: Incline DB Press | E12: 3 | F12: 8 | G12: 12 | H12: 8 | I12: =IF(OR(F12="",G12=""),"",F12*G12) | J12: =IF(OR(F12="",G12=""),"",ROUND(G12*(1+F12/30),1)) | K12: hold 12, climb 10/10/10
A13: 46146 | B13: =IF(A13="","",IFERROR(INT((A13-DATE(2026,4,27))/7)+1,"")) | C13: Upper A | D13: Lat Pulldown | E13: 1 | F13: 10 | G13: 35 | H13: 7 | I13: =IF(OR(F13="",G13=""),"",F13*G13) | J13: =IF(OR(F13="",G13=""),"",ROUND(G13*(1+F13/30),1))
A14: 46146 | B14: =IF(A14="","",IFERROR(INT((A14-DATE(2026,4,27))/7)+1,"")) | C14: Upper A | D14: Lat Pulldown | E14: 2 | F14: 10 | G14: 35 | H14: 8 | I14: =IF(OR(F14="",G14=""),"",F14*G14) | J14: =IF(OR(F14="",G14=""),"",ROUND(G14*(1+F14/30),1))
A15: 46146 | B15: =IF(A15="","",IFERROR(INT((A15-DATE(2026,4,27))/7)+1,"")) | C15: Upper A | D15: Lat Pulldown | E15: 3 | F15: 10 | G15: 35 | H15: 8 | I15: =IF(OR(F15="",G15=""),"",F15*G15) | J15: =IF(OR(F15="",G15=""),"",ROUND(G15*(1+F15/30),1)) | K15: bump 37.5 next
A16: 46146 | B16: =IF(A16="","",IFERROR(INT((A16-DATE(2026,4,27))/7)+1,"")) | C16: Upper A | D16: Pec Deck | E16: 1 | F16: 12 | G16: 7.5 | H16: 9 | I16: =IF(OR(F16="",G16=""),"",F16*G16) | J16: =IF(OR(F16="",G16=""),"",ROUND(G16*(1+F16/30),1))
A17: 46146 | B17: =IF(A17="","",IFERROR(INT((A17-DATE(2026,4,27))/7)+1,"")) | C17: Upper A | D17: Pec Deck | E17: 2 | F17: 12 | G17: 7.5 | H17: 9 | I17: =IF(OR(F17="",G17=""),"",F17*G17) | J17: =IF(OR(F17="",G17=""),"",ROUND(G17*(1+F17/30),1))
A18: 46146 | B18: =IF(A18="","",IFERROR(INT((A18-DATE(2026,4,27))/7)+1,"")) | C18: Upper A | D18: Pec Deck | E18: 3 | F18: 12 | G18: 7.5 | H18: 9 | I18: =IF(OR(F18="",G18=""),"",F18*G18) | J18: =IF(OR(F18="",G18=""),"",ROUND(G18*(1+F18/30),1)) | K18: hold 7.5, climb 15/15/15
A19: 46146 | B19: =IF(A19="","",IFERROR(INT((A19-DATE(2026,4,27))/7)+1,"")) | C19: Upper A | D19: Face Pull | E19: 1 | F19: 15 | G19: 10 | H19: 8 | I19: =IF(OR(F19="",G19=""),"",F19*G19) | J19: =IF(OR(F19="",G19=""),"",ROUND(G19*(1+F19/30),1))
A20: 46146 | B20: =IF(A20="","",IFERROR(INT((A20-DATE(2026,4,27))/7)+1,"")) | C20: Upper A | D20: Face Pull | E20: 2 | F20: 14 | G20: 10 | H20: 9 | I20: =IF(OR(F20="",G20=""),"",F20*G20) | J20: =IF(OR(F20="",G20=""),"",ROUND(G20*(1+F20/30),1))
A21: 46146 | B21: =IF(A21="","",IFERROR(INT((A21-DATE(2026,4,27))/7)+1,"")) | C21: Upper A | D21: Face Pull | E21: 3 | F21: 14 | G21: 10 | H21: 8 | I21: =IF(OR(F21="",G21=""),"",F21*G21) | J21: =IF(OR(F21="",G21=""),"",ROUND(G21*(1+F21/30),1)) | K21: bump 11-12 next
A22: 46146 | B22: =IF(A22="","",IFERROR(INT((A22-DATE(2026,4,27))/7)+1,"")) | C22: Upper A | D22: Triceps Pushdown | E22: 1 | F22: 12 | G22: 10 | H22: 8 | I22: =IF(OR(F22="",G22=""),"",F22*G22) | J22: =IF(OR(F22="",G22=""),"",ROUND(G22*(1+F22/30),1))
A23: 46146 | B23: =IF(A23="","",IFERROR(INT((A23-DATE(2026,4,27))/7)+1,"")) | C23: Upper A | D23: Triceps Pushdown | E23: 2 | F23: 12 | G23: 10 | H23: 8 | I23: =IF(OR(F23="",G23=""),"",F23*G23) | J23: =IF(OR(F23="",G23=""),"",ROUND(G23*(1+F23/30),1))
A24: 46146 | B24: =IF(A24="","",IFERROR(INT((A24-DATE(2026,4,27))/7)+1,"")) | C24: Upper A | D24: Triceps Pushdown | E24: 3 | F24: 12 | G24: 10 | H24: 8 | I24: =IF(OR(F24="",G24=""),"",F24*G24) | J24: =IF(OR(F24="",G24=""),"",ROUND(G24*(1+F24/30),1)) | K24: bump 11-12 next
A25: 46146 | B25: =IF(A25="","",IFERROR(INT((A25-DATE(2026,4,27))/7)+1,"")) | C25: Upper A | D25: DB Curl | E25: 1 | F25: 12 | G25: 6 | H25: 8 | I25: =IF(OR(F25="",G25=""),"",F25*G25) | J25: =IF(OR(F25="",G25=""),"",ROUND(G25*(1+F25/30),1))
A26: 46146 | B26: =IF(A26="","",IFERROR(INT((A26-DATE(2026,4,27))/7)+1,"")) | C26: Upper A | D26: DB Curl | E26: 2 | F26: 12 | G26: 6 | H26: 8 | I26: =IF(OR(F26="",G26=""),"",F26*G26) | J26: =IF(OR(F26="",G26=""),"",ROUND(G26*(1+F26/30),1))
A27: 46146 | B27: =IF(A27="","",IFERROR(INT((A27-DATE(2026,4,27))/7)+1,"")) | C27: Upper A | D27: DB Curl | E27: 3 | F27: 12 | G27: 6 | H27: 8 | I27: =IF(OR(F27="",G27=""),"",F27*G27) | J27: =IF(OR(F27="",G27=""),"",ROUND(G27*(1+F27/30),1)) | K27: bump 7-8 next
A28: 46147 | B28: =IF(A28="","",IFERROR(INT((A28-DATE(2026,4,27))/7)+1,"")) | C28: Lower A | D28: Back Squat | E28: 1 | F28: 7 | G28: 35 | H28: 8 | I28: =IF(OR(F28="",G28=""),"",F28*G28) | J28: =IF(OR(F28="",G28=""),"",ROUND(G28*(1+F28/30),1))
A29: 46147 | B29: =IF(A29="","",IFERROR(INT((A29-DATE(2026,4,27))/7)+1,"")) | C29: Lower A | D29: Back Squat | E29: 2 | F29: 7 | G29: 35 | H29: 8 | I29: =IF(OR(F29="",G29=""),"",F29*G29) | J29: =IF(OR(F29="",G29=""),"",ROUND(G29*(1+F29/30),1))
A30: 46147 | B30: =IF(A30="","",IFERROR(INT((A30-DATE(2026,4,27))/7)+1,"")) | C30: Lower A | D30: Back Squat | E30: 3 | F30: 6 | G30: 35 | H30: 8 | I30: =IF(OR(F30="",G30=""),"",F30*G30) | J30: =IF(OR(F30="",G30=""),"",ROUND(G30*(1+F30/30),1))
A31: 46147 | B31: =IF(A31="","",IFERROR(INT((A31-DATE(2026,4,27))/7)+1,"")) | C31: Lower A | D31: Back Squat | E31: 4 | F31: 6 | G31: 35 | H31: 8 | I31: =IF(OR(F31="",G31=""),"",F31*G31) | J31: =IF(OR(F31="",G31=""),"",ROUND(G31*(1+F31/30),1)) | K31: hold 35, climb 7/7/7/7
A32: 46147 | B32: =IF(A32="","",IFERROR(INT((A32-DATE(2026,4,27))/7)+1,"")) | C32: Lower A | D32: Romanian Deadlift | E32: 1 | F32: 10 | G32: 30 | H32: 8 | I32: =IF(OR(F32="",G32=""),"",F32*G32) | J32: =IF(OR(F32="",G32=""),"",ROUND(G32*(1+F32/30),1))
A33: 46147 | B33: =IF(A33="","",IFERROR(INT((A33-DATE(2026,4,27))/7)+1,"")) | C33: Lower A | D33: Romanian Deadlift | E33: 2 | F33: 10 | G33: 30 | H33: 8 | I33: =IF(OR(F33="",G33=""),"",F33*G33) | J33: =IF(OR(F33="",G33=""),"",ROUND(G33*(1+F33/30),1))
A34: 46147 | B34: =IF(A34="","",IFERROR(INT((A34-DATE(2026,4,27))/7)+1,"")) | C34: Lower A | D34: Romanian Deadlift | E34: 3 | F34: 8 | G34: 30 | H34: 8 | I34: =IF(OR(F34="",G34=""),"",F34*G34) | J34: =IF(OR(F34="",G34=""),"",ROUND(G34*(1+F34/30),1)) | K34: hold 30, climb 10/10/10
A35: 46147 | B35: =IF(A35="","",IFERROR(INT((A35-DATE(2026,4,27))/7)+1,"")) | C35: Lower A | D35: Leg Press | E35: 1 | F35: 12 | G35: 20 | H35: 7 | I35: =IF(OR(F35="",G35=""),"",F35*G35) | J35: =IF(OR(F35="",G35=""),"",ROUND(G35*(1+F35/30),1))
A36: 46147 | B36: =IF(A36="","",IFERROR(INT((A36-DATE(2026,4,27))/7)+1,"")) | C36: Lower A | D36: Leg Press | E36: 2 | F36: 12 | G36: 20 | H36: 8 | I36: =IF(OR(F36="",G36=""),"",F36*G36) | J36: =IF(OR(F36="",G36=""),"",ROUND(G36*(1+F36/30),1))
A37: 46147 | B37: =IF(A37="","",IFERROR(INT((A37-DATE(2026,4,27))/7)+1,"")) | C37: Lower A | D37: Leg Press | E37: 3 | F37: 11 | G37: 20 | H37: 8 | I37: =IF(OR(F37="",G37=""),"",F37*G37) | J37: =IF(OR(F37="",G37=""),"",ROUND(G37*(1+F37/30),1)) | K37: bump 22.5-25 next
A38: 46147 | B38: =IF(A38="","",IFERROR(INT((A38-DATE(2026,4,27))/7)+1,"")) | C38: Lower A | D38: Lying Leg Curl | E38: 1 | F38: 12 | G38: 15 | H38: 6 | I38: =IF(OR(F38="",G38=""),"",F38*G38) | J38: =IF(OR(F38="",G38=""),"",ROUND(G38*(1+F38/30),1)) | K38: warm-up, bumped
A39: 46147 | B39: =IF(A39="","",IFERROR(INT((A39-DATE(2026,4,27))/7)+1,"")) | C39: Lower A | D39: Lying Leg Curl | E39: 2 | F39: 11 | G39: 20 | H39: 8 | I39: =IF(OR(F39="",G39=""),"",F39*G39) | J39: =IF(OR(F39="",G39=""),"",ROUND(G39*(1+F39/30),1))
A40: 46147 | B40: =IF(A40="","",IFERROR(INT((A40-DATE(2026,4,27))/7)+1,"")) | C40: Lower A | D40: Lying Leg Curl | E40: 3 | F40: 10 | G40: 20 | H40: 8 | I40: =IF(OR(F40="",G40=""),"",F40*G40) | J40: =IF(OR(F40="",G40=""),"",ROUND(G40*(1+F40/30),1)) | K40: hold 20, climb 12/12/12
...

Sheet Running Log
A1: Date | B1: Week | C1: Distance (km) | D1: Time (min) | E1: Pace (min/km) | F1: Avg HR | G1: Max HR | H1: RPE | I1: Type | J1: Notes | K1: Bike km
A2: 46150 | B2: =IF(A2="","",IFERROR(INT((A2-DATE(2026,4,27))/7)+1,"")) | C2: 5 | D2: 25.97 | E2: =IF(OR(C2="",D2=""),"",TEXT(D2/C2/1440,"m:ss")) | F2: 176 | G2: 204 | H2: 9 | I2: Other | J2: 5K PR 25:58 @5:12/km. Z5 65%, planned Z2 — full CNS dump
A3: 46159 | B3: =IF(A3="","",IFERROR(INT((A3-DATE(2026,4,27))/7)+1,"")) | C3: 5.2 | D3: 35 | E3: =IF(OR(C3="",D3=""),"",TEXT(D3/C3/1440,"m:ss")) | F3: 160 | G3: 0 | H3: 3 | I3: Easy | J3: Sun Z2 chill 6:43/km; avg HR 160; max not recorded; aerobic base held
A4: 46182 | B4: =IF(A4="","",IFERROR(INT((A4-DATE(2026,4,27))/7)+1,"")) | C4: 6 | D4: 38.08 | E4: =IF(OR(C4="",D4=""),"",TEXT(D4/C4/1440,"m:ss")) | F4: 165 | G4: 181 | H4: 6 | I4: Easy | J4: 6:21/km; cadence 162 (+7 vs W0 155); Z3 49%+Z4 45% — too hot, cap HR ≤150 next; shin HELD, no pinpoint
A5: 46184 | B5: =IF(A5="","",IFERROR(INT((A5-DATE(2026,4,27))/7)+1,"")) | C5: 6 | D5: 45.8 | E5: =IF(OR(C5="",D5=""),"",TEXT(D5/C5/1440,"m:ss")) | F5: 149 | G5: 164 | H5: 3 | I5: Easy | J5: 7:38/km; cadence 162; 25%Z2/73%Z3 — pace fix landed (HR 165->149, RPE 6->3); shin clean
A6: 46187 | B6: =IF(A6="","",IFERROR(INT((A6-DATE(2026,4,27))/7)+1,"")) | C6: 14 | D6: 108.87 | E6: =IF(OR(C6="",D6=""),"",TEXT(D6/C6/1440,"m:ss")) | F6: 152 | G6: 171 | H6: 5 | I6: Long | J6: LONG #1 off layoff. 7:46/km; cadence 161; 91%Z2; walk breaks k5/k9/k12; 71 g in-run carbs; shin perfect
A7: 46189 | B7: =IF(A7="","",IFERROR(INT((A7-DATE(2026,4,27))/7)+1,"")) | C7: 7 | D7: 46.8 | E7: =IF(OR(C7="",D7=""),"",TEXT(D7/C7/1440,"m:ss")) | F7: 148 | G7: 167 | H7: 6 | I7: Easy | J7: 6:41/km; cadence 164 (+2-3, one short of 165); avg HR 148 in 145-155 band, 91% Z2; shin clean, everything fine
A8: 46191 | B8: =IF(A8="","",IFERROR(INT((A8-DATE(2026,4,27))/7)+1,"")) | C8: 10 | D8: 73.73 | E8: =IF(OR(C8="",D8=""),"",TEXT(D8/C8/1440,"m:ss")) | F8: 150 | G8: 165 | H8: 4 | I8: Easy | J8: 7:22/km; cadence 164; 96%Z2 = best zone control; k7 shin blip cleared in-run; EASY Z2 REFERENCE
A9: 46195 | B9: =IF(A9="","",IFERROR(INT((A9-DATE(2026,4,27))/7)+1,"")) | C9: 18 | D9: 127 | E9: =IF(OR(C9="",D9=""),"",TEXT(D9/C9/1440,"m:ss")) | F9: 149 | G9: 166 | H9: 4 | I9: Long | J9: LONG #2 = LONGEST RUN EVER. 7:03/km; cadence 164; 95%Z2 under 150 cap; 100 g in-run (~47 g/hr); shin perfect; EASY Z2 REFERENCE
A10: 46201 | B10: =IF(A10="","",IFERROR(INT((A10-DATE(2026,4,27))/7)+1,"")) | C10: 7.27 | D10: 41.25 | E10: =IF(OR(C10="",D10=""),"",TEXT(D10/C10/1440,"m:ss")) | F10: 164 | G10: 197 | H10: 7 | I10: Social | J10: 5:40/km social — HOT: 31%Z2/42%Z3/19%Z4/1%Z5, avg 164; cadence 166 (FIRST >=165, breaks 164 park); flat+sunny; quality run not base
A11: 46203 | B11: =IF(A11="","",IFERROR(INT((A11-DATE(2026,4,27))/7)+1,"")) | C11: 8.03 | D11: 50.53 | E11: =IF(OR(C11="",D11=""),"",TEXT(D11/C11/1440,"m:ss")) | F11: 155 | G11: 204 | H11: 8 | I11: Social | J11: 6:18/km social — 57%Z2/35%Z3/2%Z4, avg 155 but max 204 spike; cadence 159 (regressed from 166); RPE 8 at slower pace than 6/28 = residual fatigue/heat
A12: 46222 | B12: =IF(A12="","",IFERROR(INT((A12-DATE(2026,4,27))/7)+1,"")) | C12: 8.01 | D12: 52.17 | E12: =IF(OR(C12="",D12=""),"",TEXT(D12/C12/1440,"m:ss")) | F12: 145 | G12: 162 | H12: 5 | I12: Easy | J12: BLOCK 2 W0 BENCHMARK PASSED — 6:31/km; cadence 166 (first 165+ at easy HR); 94%Z2; -51 s/km vs 6/18 at -5 bpm; first impact in ~4 wks, shin clean
A13: 46224 | B13: =IF(A13="","",IFERROR(INT((A13-DATE(2026,4,27))/7)+1,"")) | C13: 5 | D13: 33.88 | E13: =IF(OR(C13="",D13=""),"",TEXT(D13/C13/1440,"m:ss")) | F13: 147 | G13: 164 | H13: 5 | I13: Easy | J13: W1 Tue. 6:46/km; cadence 166 (2nd straight 165+ easy); 92%Z2; 2x1 min walk; run 24h post first legs day in 62d (DOMS 3/3/3) — shin clean during+after
... A18: 46271 | B18: =IF(A18="","",IFERROR(INT((A18-DATE(2026,4,27))/7)+1,"")) | C18: 10 | D18: 75.15 | E18: =IF(OR(C18="",D18=""),"",TEXT(D18/C18/1440,"m:ss")) | F18: 150 | G18: 161 | H18: 4 | I18: Long | J18: Blk2 Wk A Sun - LONG 10k, WEEK A CLOSER. 7:31/km, 97%Z2 = HIGHEST IN LOG (94 on 5k -> 80 on 6k -> 97 on 10k; easy-day discipline scaled UP with distance). Longest run since 2026-06-22 (18k); +36% step over Fri's 6k; taken 20h post-lifting instead of 48h (cali moved Fri->Sat). CADENCE 167 = BLOCK'S OLDEST OPEN ITEM CLOSED: 3rd cued run, 3rd hit (166/166/167), 1 spm off the 168 PR, held through 75 min where fatigue had every chance to drag turnover down. Never lost, only uncued - metronome every run to the race, bone lever (shorter ground contact = less tibial impact). 0 WALK BREAKS over 10k = continuous running green at 6k AND at 10k under fatigue; the 4 breaks on 9/2 were first-run-back rust, not a pattern. SHIN CLEAN check #15, 15 straight, through the biggest distance jump of the block. HONEST PACE READ: 7:31/km @ HR 150 today vs 7:08/km @ HR 145 on 9/4 = slower pace at HIGHER HR. Over 67% more distance, sunny vs 13C rain = ordinary decoupling on a re-entry long run, NOT a flag; max 161 = steady drift, no spikes. But the run sat AT the ceiling, not under it -> Wk B's 12k must OPEN SLOWER (~7:35-7:50/km early); the extra 2km comes out of the first half's pace budget, not the second half's HR. RPE 4 + user: 'a bit tired but could have done 15km chill' = engine ahead of chassis and ahead of plan. Extraction audit verdict: the un-cashed lever is COMPLIANCE (3 of 4 runs run, 21 of 26 km), NOT more km - long-run ramp is already stacked at its ceiling and bone, not lungs, sets the ceiling. Wk B long stays 12k; set distance by bone, not by breath. Fuel during run: half banana + 80% Powerade ~30-40g carbs / 75 min = on the 30 g/h prescription, unprompted. Kcal 2693 vs ~2600 long-day cap = +93 = FUEL DRIFT ARRESTED (was +977/+546/+937). Protein 170 (down from 227). Creatine Y.
A19: 46272 | B19: =IF(A19="","",IFERROR(INT((A19-DATE(2026,4,27))/7)+1,"")) | C19: 5 | D19: 36.5 | E19: =IF(OR(C19="",D19=""),"",TEXT(D19/C19/1440,"m:ss")) | F19: 147 | G19: 162 | H19: 3 | I19: Easy | J19: Blk2 Wk B Mon - 5k easy shakeout, 24h after Sun's 10k long. Monday was a REST day until two same-day schedule swaps (cali #3 Mon->Wed, cali #4 Fri->Sat) would have left 6 consecutive loaded days on one rest day; rebalanced by spending Monday's rest on the week's shortest run and making Thursday the rest day. 7:18/km @ HR 147, 97%Z2, RPE 3 = LOWEST RUN RPE IN THE LOG. Prescription was 7:35-7:50/km -> ran ~20 s/km HOT. Allowed to stand because HR 147 held under the 150 ceiling, but it is the block's recurring pattern: feeling good becomes FASTER, not EASIER. On Sunday's 12k that costs the back half - open at 7:50 and mean it. EFFICIENCY: 7:18 @ 147 vs the clean rested comparable 7:08 @ 145 on 9/4 = 10 s/km slower at +2 bpm on a day-after-long shakeout = chassis recovering FASTER than the ramp assumed. CADENCE 167 = 4th straight cued run on target (166/166/167/167); metronome stays mandatory. 0 walk breaks, 3rd run running. SHIN CLEAN check #17. Fuel 2566 vs corrected uni-day ~2650-2700 = ~100 under, noise. Protein 169 (band 155-165). Creatine Y. Steps 9100. BIKE 24 km - uni-day commute, DISCLOSED TODAY as Tier 1 load (12 km each way, Mon-Thu = 96 km/wk, ~4-5 h, MORE clock time than the running). Zero bone cost (non-impact, does not spend the tibia budget) and it partly explains why the audits keep finding the engine ahead of the chassis. Makes the ~2400 kcal maintenance figure STALE: uni days 2650-2700, non-uni 2400, Sun long 2700. Sat+Sun are bike-free - that is what protects the long run. Wk B compliance: run 1 of 4. | K19: 24
A20: 46273 | B20: =IF(A20="","",IFERROR(INT((A20-DATE(2026,4,27))/7)+1,"")) | C20: 6 | D20: 48.22 | E20: =IF(OR(C20="",D20=""),"",TEXT(D20/C20/1440,"m:ss")) | F20: 140 | G20: 153 | H20: 1 | I20: Easy Z2 | J20: 97% Z2, cadence 163 (first cued miss), 0 walk breaks, light rain, shin clean #19. Pace obeyed prescription 8:01 vs 7:45-8:00. | K20: 24
A21: 46276 | B21: =IF(A21="","",IFERROR(INT((A21-DATE(2026,4,27))/7)+1,"")) | C21: 6 | D21: 44.3 | E21: =IF(OR(C21="",D21=""),"",TEXT(D21/C21/1440,"m:ss")) | F21: 146 | G21: 158 | H21: 2 | I21: Easy Z2 | J21: Blk2 Wk B Fri - run easy 6 k, LAST SESSION OF WK B. 7:22/km @ HR 146, 98% Z2 = HIGHEST Z2 SHARE OF THE BLOCK, max 158, RPE 2, 0 walk breaks (streak 4), chilly cloudy, 'It was a chill day.' SHIN CLEAN check #23. Fri is bike-free. ENGINE READ EXCELLENT: clean comparable is 9/4 (7:08/km @ HR 145, fully rested) -> 7:22 @ 146 shows NO drift; third consecutive run at RPE <=3. CADENCE 166 HIT BUT BOUGHT WITH SPEED - THIS RUN DOES NOT ANSWER THE OPEN QUESTION. Prescription was open ~7:50/km; actual 7:22 = 28 s/km HOT, landing back in the 7:08-7:18 band where the cue has always worked. The session's own rule called it in advance: pace under 7:40 means cadence was bought with speed, not turnover. The metronome still has ZERO successful reps below ~7:20/km; the only honest test remains 9/8 (8:01/km -> 163). THIRD REPEAT OF THE PATTERN: 9/7 ran 7:18 vs 7:35-7:50, 9/8 obeyed at 8:01, 9/11 ran 7:22 vs 7:50. The correction lands for exactly one run, then decays. Costs nothing on a 6 k; costs the back half on a 12-22 k, the only place opening pace matters. Carried forward and now overdue. PM NOT SUPPLIED - kcal, protein, creatine, steps, Friday-night symptoms written off, not reconstructed. Illness surfaced Saturday so this run was likely made on an incubating bug; HR 146 at RPE 2 shows no prodrome, so noted not weighted. WK B CLOSES HERE: runs 3 of 4, 17 of 29 km, cali 1 of 2 - Sat cali #4 and Sun long 12 k both LOST TO ILLNESS. | K21: 0
A22: 46281 | B22: =IF(A22="","",IFERROR(INT((A22-DATE(2026,4,27))/7)+1,"")) | C22: 4 | D22: 24.92 | E22: =IF(OR(C22="",D22=""),"",TEXT(D22/C22/1440,"m:ss")) | F22: 159 | G22: 176 | H22: 5 | I22: Easy re-entry | J22: Blk2 Wk C Wed - RUN RE-ENTRY 4 k, first run after illness (sick 9/12-9/14, clear 9/15) and a 5-day run gap. DONE BUT OFF-PRESCRIPTION - three rule breaches. Prescribed 7:50-8:10/km, HARD HR ceiling 140, bike HALVED to 12 km. ACTUAL 6:14/km @ avg HR 159, max 176, 47%Z2 / 51%Z3 / 2%Z4+, RPE 5, cadence 167, bike 24 km, steps 23249, chill night. User: 'Good run I was feeling good so I just ran.' (1) HR CEILING BLOWN BY 19 BPM - more time above the cap than below it, on the single most tightly capped session in the block, the illness rule's mandatory one easy SHORT run before anything loaded. (2) BLOCK GATE BREACHED - nothing above HR 150 runs before Fri Sep 25; this sat above 150 for most of its length, and at 6:14/km it was 6 s/km FASTER than 30 k race pace. (3) BIKE 24 km vs 12 - the halving WAS the re-entry recovery budget. CADENCE 167 IS VOID: a cadence number only counts if the pace instruction was obeyed, and under ~7:40/km the datapoint does not exist - at 6:14 the beat is bought with speed, not turnover. The metronome still has ZERO successful reps below ~7:20/km; 9/8 (8:01/km -> 163) remains the only honest test. ENGINE SIGNAL IS REAL AND IS THE ONE GOOD THING: 6:14/km at HR 159, RPE 5, five days detrained post-illness. The 9/06 addendum modelled race pace 6:20/km at HR 160-168 - he beat goal pace at the BOTTOM of that band and called it 5/10. This does NOT open sub-3:00 and does NOT move any distance: 4 km is 13% of the race, and sub-3:10 is gated by holding 6:20 at km 25 off a 22 k longest run, not by 4 km of pace. FINISHING PROBLEM UNCHANGED. It does make the Sep 25 benchmark very likely to clear - which is an argument for running it rested and measured, not for pre-spending it. SHIN CLEAN check #24, but the check was taken the same night and bone stress surfaces at 24-72 h -> verdict deferred to the Thu 9/17 and Fri 9/18 AM checks. Steps 23249 with no job, stacked on 24 km of bike: soft-tissue load, no bone value. MACROS NOT COUNTED 9/16 - written off, not reconstructed, not re-asked. Creatine Y. Wk C after Day 1: runs 1 of 3, 4 of 21 km. | K22: 24
A23: 46286 | B23: =IF(A23="","",IFERROR(INT((A23-DATE(2026,4,27))/7)+1,"")) | C23: 6 | D23: 47.7 | E23: =IF(OR(C23="",D23=""),"",TEXT(D23/C23/1440,"m:ss")) | F23: 145 | G23: 154 | H23: 4 | I23: Easy Z2 | J23: Wk D Mon - run easy 6 k AM (Mon<->Tue swap; cali #5 moved to Tue 9/22). 7:56/km, 99% Z2, CADENCE 170, 0 walk breaks, RPE 4, 'chill run'. SLOW-PACE CADENCE TEST - PASSED, ITEM CLOSED. Prescription was hold 7:45-8:00/km and hit 166 by SHORTENING STRIDE; pace came in at 7:56 = INSIDE the band, so the data point is VALID (no sub-7:40 void, nothing bought with speed) - the first obeyed opening pace in four tries (9/7 hot, 9/11 hot, 9/16 hot, 9/21 obeyed). Cadence 170 vs the only prior honest slow-pace test, 9/8 at 8:01/km -> 163: same pace, +7 spm, and 4 ABOVE the 166 target. The cue does NOT break at slow pace; 9/8 was one failed rep, not a pace ceiling. NEW STANDING RULE: metronome 166 is a FLOOR at every pace, held by shortening stride; overshoot to 170 is welcome, do not chase it back down. Never re-test uncued (9/2 ran that: 160). Bone lever, not cosmetic - 163->170 across Sunday's 12 k easy portion is real reduction in impact per strike, and that is exactly where the tibia budget is spent. SHIN CLEAN - check #26, 26/26 this block. HR 145 @ 7:56 vs 140 @ 8:01 on 9/8 = +5 bpm at the same pace; NOT called as drift - 9/8 was RPE 1 in light rain, today RPE 4, and a shorter quicker stride carries a small metabolic cost. Noise band. Recheck Thu 9/24. BIKE 0 km on a uni day (class 12:00-17:00, run went AM) - zero training consequence, bike has no bone value; consequence is fuel only: Monday target drops from 2650-2700 to ~2400. Creatine Y. Loaded-day count intact: Mon run (1) -> Tue cali #5 (2) -> Wed full rest; max-2 holds, and the swap now gives the RPE-6 leg cap 48 h in front of Thu's 4 k. STILL OPEN: 9/18, 9/19, 9/20 unlogged - Sun 9/27 stays provisional at 15 k if the 9/20 long happened, 13 k if it was missed or cut short. Fri 9/25 benchmark unaffected. | K23: 0
A24: 46289 | B24: =IF(A24="","",IFERROR(INT((A24-DATE(2026,4,27))/7)+1,"")) | C24: 4 | D24: 26.38 | E24: =IF(OR(C24="",D24=""),"",TEXT(D24/C24/1440,"m:ss")) | F24: 154 | G24: 167 | H24: 4 | I24: Easy Z2 | J24: Wk D Thu - run easy 4 k, day before Fri 9/25 8 k benchmark. OFF-PRESCRIPTION: prescribed open 8:00/km, never under 7:40, HR ceiling 150. ACTUAL 6:35/km @ avg HR 154, max 167, Z1 7 / Z2 80 / Z3 13, cadence 165, 0 walk breaks, RPE 4, outdoor sunny. 'All good I felt really good.' Pace floor missed ~1:05/km, HR cap broken. Pace-obedience decay: 9/7 hot, 9/8 obeyed, 9/11 hot, 9/16 hot, 9/21 obeyed, 9/24 hot. CADENCE 165 VOID (pace <7:40); note 170 @ 7:56 vs 165 @ 6:35 = longer stride at speed - metronome on for benchmark. HR drift check VOID (pace not matched to 9/21 145 @ 7:56); engine consistent with 9/16 (6:14 @ 159). SHIN CLEAN #30 (same-night; Fri AM is the gate). Benchmark cost small, Fri stands. | K24: 0
A25: 46290 | B25: =IF(A25="","",IFERROR(INT((A25-DATE(2026,4,27))/7)+1,"")) | C25: 9.01 | D25: 52.43 | E25: =IF(OR(C25="",D25=""),"",TEXT(D25/C25/1440,"m:ss")) | F25: 173 | G25: 198 | H25: 9 | I25: Benchmark | J25: Wk D Fri - 8 K BENCHMARK, AM 09:34 (flipped from PM). Total 9.01 km moving 52:26, elapsed 54:43. WU 1 k (not 2) 6:46 @ 146, cadence 159. 8 k (km 2-9): 5:42/km moving, 5:58 elapsed. Splits 5:21 @179 (hero opener) / 6:05 @172 (+42 s traffic light) / 5:59 @174 / 5:52 @177 / 5:53 @177 / 6:03 @174 / 5:48 @177 / 4:37 @190 max 198 (+44 s traffic light). Even-effort core km 3-8 = 5:57 @ HR ~175. Cadence ~166 over the 8 k (laps 163-170). No CD. RPE 9. SHIN CLEAN #32. VERDICT: sub-3:10 CONFIRMED, sub-3:00 NOT opened (opener + stops + kick inflate moving avg; longest run 10 k). Race-pace HR model holds: 6:20 ~ HR 163-168. Tibialis moved to Sat. | K25: 0
A26: 46292 | B26: =IF(A26="","",IFERROR(INT((A26-DATE(2026,4,27))/7)+1,"")) | C26: 13.01 | D26: 98.92 | E26: =IF(OR(C26="",D26=""),"",TEXT(D26/C26/1440,"m:ss")) | F26: 153 | G26: 179 | H26: 6 | I26: Long | J26: Wk D Sun - LONG 13 k, PM 15:43 (moved from AM). Moving 1:38:55, elapsed 1:46:38 (7.7 min stopped, 4.5 min at ~1.3 k). Gate 3 (legs 1 AM): 10 easy + 3 @ 6:20. Easy 10 k 8:03/km @ HR ~148, cadence ~164 (2 under floor). OPENING MISSED: km1-2 6:45/6:58 vs 7:50; km 3-9 8:15-8:36 under HR cap. Final 3 k 6:19 @171 / 6:06 @169 / 5:54 @171 = 6:06 avg @ HR 170, max 179 - kicked, not held; HR>172 rule not obeyed. Race-pace HR on fatigue ~171 (model said 163-168). Easy HR ~149 @ 8:24 vs 145 @ 7:56 (9/21) - Tue 9/29 drift check. Fuel 80 g. RPE 6. SHIN CLEAN #36. Quad/calf post 3. Wk D closed 4/4 runs, 32 km. Strava 20353804584. | K26: 0
A27: 46294 | B27: =IF(A27="","",IFERROR(INT((A27-DATE(2026,4,27))/7)+1,"")) | C27: 6 | D27: 41.77 | E27: =IF(OR(C27="",D27=""),"",TEXT(D27/C27/1440,"m:ss")) | F27: 142 | G27: 155 | H27: 4 | I27: Easy | J27: Wk E Tue - EASY 6 k DRIFT CHECK, PM 15:31. Moving 41:46 (6:57/km), elapsed 46:37 (4.3 min stop ~0.7 k). Splits 6:43@127 / 6:42@146 / 6:45@148 / 7:13@144 / 7:27@144 / 6:55@145. Km 2-6 = 7:00/km @ HR 145.5 vs 145 @ 7:56 (9/21) -> check technically void (pace under 7:40) but NO DRIFT: same HR 56 s/km faster. Thu run stays. Opening missed 4th straight (6:43 vs 7:50). Cadence 164 (laps 165/166/166/164/163 - fades late, 2 under floor 2nd run running). RPE 4, 0 walk breaks. SHIN CLEAN #40. Quad/calf post 2. Strava 20378851247. | K27: 0
A28: 46301 | B28: =IF(A28="","",IFERROR(INT((A28-DATE(2026,4,27))/7)+1,"")) | C28: 5 | D28: 28.3 | E28: =IF(OR(C28="",D28=""),"",TEXT(D28/C28/1440,"m:ss")) | F28: 160 | G28: 176 | H28: 6 | I28: Steady | J28: 5K Wk 1 Tue - ROAD 5 k (track 6x400 swapped, user). PM 12:40. Moving 28:18 (5:39), elapsed 35:44 (6.5 min stop ~0.65 k). Splits 5:59@133 / 5:34@163 / 5:34@167 / 5:32@171 / 5:38@168. Main 4 k @ 5:34 HR ~167 max 176 vs prescribed 3 k @ 6:00 cap 172 - RAN HOT. No strides visible, no CD. Cadence 163. RPE 6. Engine: 9/25 5:57@175 RPE 9 -> 5:34@167 RPE 6; 5K est ~26:30-27:00. SHIN CLEAN #41. Fri threshold up to 5:35-5:40. Strava 20472528970. | K28: 0
A29: 46303 | B29: =IF(A29="","",IFERROR(INT((A29-DATE(2026,4,27))/7)+1,"")) | C29: 5.12 | D29: 36.48 | E29: =IF(OR(C29="",D29=""),"",TEXT(D29/C29/1440,"m:ss")) | F29: 146 | G29: 166 | H29: 5 | I29: Easy+Strides | J29: 5K Wk 1 Thu - EASY 5 k + 6x20 s STRIDES. PM 18:23, light rain. Moving 36:29 (7:08), elapsed 41:39 (~4.7 min stop ~0.67 k). Laps 6:19@130 (GPS start) / 6:51@152 / 7:10@149 / 7:39@148 / 7:39@149 (strides) / 0.12 k. Easy km 2-4 = 7:13 @ ~150, pace obeyed. Cadence easy km 164/166/166/167 (floor back). Strides 6/6 smooth but GPS ~3:55-4:58, mostly 4:10-4:30 vs prescribed 5:10-5:20 = ran hot. RPE 5. SHIN CLEAN #45. Strava 20505117221. | K29: 0
A30: 46309 | B30: =IF(A30="","",IFERROR(INT((A30-DATE(2026,4,27))/7)+1,"")) | C30: 5.03 | D30: 37.53 | E30: =IF(OR(C30="",D30=""),"",TEXT(D30/C30/1440,"m:ss")) | F30: 149 | G30: 170 | H30: 5 | I30: Easy+Strides | J30: 5K Wk 2 Wed - EASY 5 k + 6x20 s STRIDES, re-entry after 6 run-free days (10/9-10/13 dark). PM 16:55, sunny. Moving = elapsed 37:32 (7:28), no stops. Laps 7:00@138 / 7:20@152 / 7:16@152 / 8:11@148 (+8 m) / 7:37@152 (strides). Cadence easy km 165/166/164/163 (under floor km 3-4). Strides 6/6, GPS ~5:00/4:23/4:46/4:38/5:08/4:54 - closer to 5:10-5:20 than 10/8. RPE 5, walk 0. SHIN CLEAN #46. Strava 20583383940. | K30: 0
A31: 46310 | B31: =IF(A31="","",IFERROR(INT((A31-DATE(2026,4,27))/7)+1,"")) | C31: 4.02 | D31: 28.85 | E31: =IF(OR(C31="",D31=""),"",TEXT(D31/C31/1440,"m:ss")) | F31: 142 | G31: 157 | I31: Easy | J31: 5K Wk 2 Thu - EASY 4 k, AM 07:49 before Gym #2. Moving 28:51 (7:11), elapsed 29:36 (35 s stop km 3). Laps 7:05@124 / 7:00@147 / 7:34@146 (+9 m) / 7:05@151. HR cap obeyed. Cadence 160/163/162/162 - under 166 floor all run. RPE n/r. SHIN CLEAN #48. Strava 20591443035. | K31: 0
A32: 46312 | B32: =IF(A32="","",IFERROR(INT((A32-DATE(2026,4,27))/7)+1,"")) | C32: 6.82 | D32: 42.5 | E32: =IF(OR(C32="",D32=""),"",TEXT(D32/C32/1440,"m:ss")) | F32: 161 | G32: 184 | I32: Threshold | J32: 5K Wk 2 Sat - THRESHOLD 2x~1.9 k, Sonderborg (travel). PM 13:51. Moving 42:30 (6:14), elapsed 45:23. WU ~2 k 6:30-7:00 @145-155; 3 strides ~4:00-4:30 (hot); rep 1 ~1.9 k @ ~5:26-5:31 HR 177-182; ~2:15 jog; rep 2 ~1.9 k @ ~5:33 HR 176-184, faded last ~750 m; CD skipped. HR cap 175 broken both reps: +10 bpm vs 10/6 at same pace. Cadence reps 165/167. RPE n/r, shin n/r. Strava 20620965276. | K32: 0
A33: 46316 | B33: =IF(A33="","",IFERROR(INT((A33-DATE(2026,4,27))/7)+1,"")) | C33: 6.17 | D33: 41 | E33: =IF(OR(C33="",D33=""),"",TEXT(D33/C33/1440,"m:ss")) | F33: 158 | G33: 198 | H33: 8 | I33: 3K TT | J33: 5K Wk 3 Wed - 3 K TIME TRIAL, road, Ballerup, AM 07:28. Total moving 41:00 / elapsed 41:56. WU 2 k 7:36@132 / 7:23@149 (cad 162/161), 4 strides ~4:20-4:35. TT 3.00 k GPS: km 5:00 / 5:00 (5:42 elapsed, ~43 s standing ~1.5 k, HR 190->150) / 5:01 = 15:00 moving / 15:42 elapsed. TT HR ~183-187, max 198, cad 166. RPE 8. CD skipped. GATE: sub-27 CONFIRMED, PR not opened (borderline + rest) -> run 2 4x1 k @ 5:10-5:12 decides PR. SHIN CLEAN #50. Strava 20670617068. | K33: 0
B34: =IF(A34="","",IFERROR(INT((A34-DATE(2026,4,27))/7)+1,"")) | E34: =IF(OR(C34="",D34=""),"",TEXT(D34/C34/1440,"m:ss"))
B35: =IF(A35="","",IFERROR(INT((A35-DATE(2026,4,27))/7)+1,"")) | E35: =IF(OR(C35="",D35=""),"",TEXT(D35/C35/1440,"m:ss"))
B36: =IF(A36="","",IFERROR(INT((A36-DATE(2026,4,27))/7)+1,"")) | E36: =IF(OR(C36="",D36=""),"",TEXT(D36/C36/1440,"m:ss"))
B37: =IF(A37="","",IFERROR(INT((A37-DATE(2026,4,27))/7)+1,"")) | E37: =IF(OR(C37="",D37=""),"",TEXT(D37/C37/1440,"m:ss"))
B38: =IF(A38="","",IFERROR(INT((A38-DATE(2026,4,27))/7)+1,"")) | E38: =IF(OR(C38="",D38=""),"",TEXT(D38/C38/1440,"m:ss"))
B39: =IF(A39="","",IFERROR(INT((A39-DATE(2026,4,27))/7)+1,"")) | E39: =IF(OR(C39="",D39=""),"",TEXT(D39/C39/1440,"m:ss"))
B40: =IF(A40="","",IFERROR(INT((A40-DATE(2026,4,27))/7)+1,"")) | E40: =IF(OR(C40="",D40=""),"",TEXT(D40/C40/1440,"m:ss"))
B41: =IF(A41="","",IFERROR(INT((A41-DATE(2026,4,27))/7)+1,"")) | E41: =IF(OR(C41="",D41=""),"",TEXT(D41/C41/1440,"m:ss"))
B42: =IF(A42="","",IFERROR(INT((A42-DATE(2026,4,27))/7)+1,"")) | E42: =IF(OR(C42="",D42=""),"",TEXT(D42/C42/1440,"m:ss"))
B43: =IF(A43="","",IFERROR(INT((A43-DATE(2026,4,27))/7)+1,"")) | E43: =IF(OR(C43="",D43=""),"",TEXT(D43/C43/1440,"m:ss"))
B44: =IF(A44="","",IFERROR(INT((A44-DATE(2026,4,27))/7)+1,"")) | E44: =IF(OR(C44="",D44=""),"",TEXT(D44/C44/1440,"m:ss"))
...

Sheet Body Metrics
A1: Date | B1: Week | C1: Body Weight (kg) | D1: Sleep (hrs) | E1: Waist (cm) | F1: Chest (cm) | G1: Arm (cm) | H1: Thigh (cm) | I1: Notes
A2: 46141 | B2: =IF(A2="","",IFERROR(INT((A2-DATE(2026,4,27))/7)+1,"")) | C2: 77.7 | D2: 8 | I2: Wk 1 Wed AM
A3: 46149 | B3: =IF(A3="","",IFERROR(INT((A3-DATE(2026,4,27))/7)+1,"")) | C3: 77.3 | D3: 9 | I3: Wk 2 Thu PM (post Upper B)
A4: 46150 | B4: =IF(A4="","",IFERROR(INT((A4-DATE(2026,4,27))/7)+1,"")) | C4: 77 | D4: 8 | I4: Wk 2 Fri PM (post 5K PR)
A5: 46151 | B5: =IF(A5="","",IFERROR(INT((A5-DATE(2026,4,27))/7)+1,"")) | C5: 77 | D5: 8 | I5: Wk 2 Sat PM (rest, alc 5u)
A6: 46152 | B6: =IF(A6="","",IFERROR(INT((A6-DATE(2026,4,27))/7)+1,"")) | C6: 77 | D6: 7 | I6: Wk 2 Sun PM (post Lower B)
A7: 46153 | B7: =IF(A7="","",IFERROR(INT((A7-DATE(2026,4,27))/7)+1,"")) | C7: 77.2 | D7: 7.83 | I7: Wk 3 Mon PM (post Upper A)
A8: 46155 | B8: =IF(A8="","",IFERROR(INT((A8-DATE(2026,4,27))/7)+1,"")) | C8: 77.2 | D8: 8.6 | I8: Wk 3 Wed PM (post Lower A)
A9: 46156 | B9: =IF(A9="","",IFERROR(INT((A9-DATE(2026,4,27))/7)+1,"")) | C9: 77.3 | D9: 8 | I9: Wk 3 Thu PM (rest, protein 90g)
A10: 46157 | B10: =IF(A10="","",IFERROR(INT((A10-DATE(2026,4,27))/7)+1,"")) | C10: 77.7 | D10: 9 | I10: Wk 3 Fri AM (BW AM-only from here)
A11: 46158 | B11: =IF(A11="","",IFERROR(INT((A11-DATE(2026,4,27))/7)+1,"")) | C11: 76.7 | D11: 7.5 | I11: Wk 3 Sat AM (-1kg vs Fri; slow cut, NOT illness)
A12: 46159 | B12: =IF(A12="","",IFERROR(INT((A12-DATE(2026,4,27))/7)+1,"")) | C12: 76.2 | D12: 8 | I12: Wk 3 Sun AM (cut on-plan; AM slope toward ~73)
A13: 46160 | B13: =IF(A13="","",IFERROR(INT((A13-DATE(2026,4,27))/7)+1,"")) | C13: 76.2 | D13: 8 | I13: Wk 4 Mon AM (flat vs Sun; post-Lower-B water noise, not stall)
... A26: 46228 | B26: =IF(A26="","",IFERROR(INT((A26-DATE(2026,4,27))/7)+1,"")) | C26: 77.85 | D26: 7.53 | I26: W1 Sat AM run day (RHR 43 d-1 post-Push bump cleared; shin clean check #7; Push DOMS 3->1 at 48h, legs 0; BW +0.65 single-day spike ignore, 7d ~77.4; bed 12:39am 2nd straight post-midnight, sleep 7:32 q6.5 week-low)
A27: 46229 | B27: =IF(A27="","",IFERROR(INT((A27-DATE(2026,4,27))/7)+1,"")) | I27: W1 Sun — LONG 10k SKIPPED, unplanned REST. NO AM/PM DATA CAPTURED (row exists to document the gap, blanks are genuine). User: legs dont feel good. Shin was clean 8/8 all week — FATIGUE not bone. W1 closes 16/26 km, 3/4 runs, ZERO long runs. Cause: only 1 true rest day in 7 + Sat-run/Sun-long back-to-back + ~44 km/wk unmodeled walking from waiter job. No Sunday review ran; backfilled 7/27.
A28: 46230 | B28: =IF(A28="","",IFERROR(INT((A28-DATE(2026,4,27))/7)+1,"")) | C28: 77.05 | D28: 10 | I28: W2 Mon REST (2nd consecutive; now the template rest day). AM GREEN — RHR 43 (d-1, under W1 avg 44.8, band 41-46) = systemic fatigue cleared. Shin NO PAIN = clean check #9, bone never involved. Legs cleared quad1/ham1/glute0 BUT CALF HELD AT 2 = the waiter job's signature tissue -> validates dropping Standing Calf Raise. BW 77.05 = block low, Sat 77.85 spike resolved, 7d avg 77.25 flat at maintenance (cut opens Aug 10). Sleep 10h q10 = best of block. Bed 2am/wake 12pm — structural on 22:00-23:00 shift nights, not a discipline flag. PM not yet supplied.
A29: 46265 | B29: =IF(A29="","",IFERROR(INT((A29-DATE(2026,4,27))/7)+1,"")) | C29: 75 | I29: Block 2 Wk A Mon. BW 75.0 = CUT CLOSED target hit (77.05 on 7/27, 77.6 block start). Maintenance ~2400 kcal to race. First entry after the 34-day dark gap Jul 29 - Aug 30 (~2 runs, no logging). Cali Full Body done 16:20-17:30, 28 sets, shin CLEAN.
A30: 46266 | B30: =IF(A30="","",IFERROR(INT((A30-DATE(2026,4,27))/7)+1,"")) | I30: Wk A Tue — planned 5k easy Z2 SKIPPED, rest day taken. No AM/PM data captured (blanks genuine). Not a bone flag; rest after first lifting session in 39 days.
A31: 46267 | B31: =IF(A31="","",IFERROR(INT((A31-DATE(2026,4,27))/7)+1,"")) | I31: Wk A Wed run day. No AM block captured (blanks genuine) - session reported PM. Shin clean #10, legs good "ready to build back". Kcal 3377 vs ~2400 maintenance = +977 SURPLUS day; protein 157 in band, creatine Y. Cut is closed at 75.0 - hold it, the economy gain is banked. Watch 7d BW.
A32: 46268 | B32: =IF(A32="","",IFERROR(INT((A32-DATE(2026,4,27))/7)+1,"")) | I32: Wk A Thu — full REST (swapped with Wed run). No AM/PM data captured (blanks genuine). BW still not logged since 75.0 on 8/31.
A33: 46269 | B33: =IF(A33="","",IFERROR(INT((A33-DATE(2026,4,27))/7)+1,"")) | I33: Wk A Fri run day (6k easy, cali moved to Sat 9/5). No AM block captured (blanks genuine). Shin CLEAN #12, legs fresh. Kcal 2946 vs ~2400 maintenance = +546 SURPLUS, 2nd of 2 logged days (9/2 was +977) = ~+1500 drift over the week; protein 151 (in band, at floor - sit 155-165 on a ramping week); creatine Y. BW AM MISSING 3 STRAIGHT DAYS while running +500 to +1000/day - the week's one blind spot. Cut closed at 75.0 TO HOLD IT; the ~5-6 s/km economy gain is banked. Log BW 9/5 AM.
A34: 46270 | B34: =IF(A34="","",IFERROR(INT((A34-DATE(2026,4,27))/7)+1,"")) | C34: 75.85 | D34: 9.35 | I34: Wk A Sat — cali session 2 (moved from Fri). AM FULL GREEN: sleep 9:21 q8 = best in log, RHR 44 delta 0, motivation/energy 10, stress 1, joints all clear. SHIN CLEAN check #13 (13 straight), holds post-session. DOMS quad/ham/glute 1 (8/31 RPE6 leg cap did its job), upper all 0, calf 2 + tib 2 = residue from 9/2+9/4 runs and the tibialis raises, NOT bone. BW 75.85 = FIRST WEIGH-IN IN 5 DAYS, +0.85 over 75.0 on 8/31; mostly glycogen+water from two runs back on, ~0.2 kg real. FUEL RED FLAG: 3337 kcal = +937, THIRD consecutive surplus day (9/2 +977, 9/4 +546, 9/5 +937 = ~+2460 over 3 days ~= +0.3 kg fat). One day was noise, three of three is a pattern. Cut closed at 75.0 TO HOLD 75.0 - the ~5-6 s/km economy gain is the cheapest time available for Oct 11 and is being handed back. Protein 227 g = 3.0 g/kg, ~60 g over the 155-165 band for zero benefit; trimming to 165 alone is ~-250 kcal. Creatine Y. Sunday cap ~2600 - a long-run day earns carbs, not a third +900.
A35: 46271 | B35: =IF(A35="","",IFERROR(INT((A35-DATE(2026,4,27))/7)+1,"")) | C35: 75.85 | D35: 9.5 | I35: Wk A Sun - LONG 10k, week closer. AM GREEN: sleep 9:30 q9, RHR 46 (delta +2 vs baseline 44 = noise off a 65-min lifting session), motivation 9, energy 10, stress 1, joints all clear. SHIN CLEAN check #14 (pre-run) and #15 (post-run). DOMS legs ALL 1 (quad/ham/glute/calf/tib) at 20h post-cali - Sat's calf 2 / tib 2 cleared overnight. SECOND consecutive time the RPE 6 leg cap delivered fresh legs into a run day, this time off 24h not 48h: the Fri->Sat cali move cost nothing. Cap VALIDATED, not merely tolerated. Upper DOMS chest 3 / delt 3 / back 2 / arm 2 = the 9/5 push/pull fix landing on schedule (push went 5.9 -> 8.0 RPE); irrelevant to running. BW 75.85 = FLAT vs 9/5, first non-rising point in the fuel drift. 9/5 ran +937 kcal and the scale did not move -> confirms the +0.85 over the 75.0 close (8/31) is mostly glycogen + water, not fat. Flag NOT closed - weigh in Mon 9/7 AM, that reading makes the 7-day trend call. FUEL DRIFT ARRESTED: 2693 kcal vs the ~2600 long-day cap = +93, after +977 (9/2), +546 (9/4), +937 (9/5). Protein 170 g, down from 227, 5 over band on a long day = the correction landed. Creatine Y. Non-long days ~2400, protein 155-165.
A36: 46272 | B36: =IF(A36="","",IFERROR(INT((A36-DATE(2026,4,27))/7)+1,"")) | C36: 75.85 | D36: 9 | I36: Wk B Mon - 5k easy shakeout (was a rest day; converted after two cali swaps). AM FULL GREEN: sleep 9:00 q10, RHR 46 delta -2, motivation 10, energy 10, stress 2, joints all clear. SHIN PERFECT check #16 (pre) and #17 (post-run). DOMS legs ALL 1 (quad/ham/glute/calf) at 2 days post-cali = RPE 6 leg cap validated a 3rd time. Upper: shoulder 3, chest 2, back 1, arm 1 = 9/5 pressing residue at 48h; this is WHY moving cali Mon->Wed is a net positive (shoulders get 4 days instead of 2). BW 75.85 = THIRD CONSECUTIVE FLAT READING (9/5, 9/6, 9/7) after +937 and +93 kcal days. TREND CALL MADE: the +0.85 over the 8/31 close of 75.0 is glycogen + water, NOT fat - fuel-drift flag CLOSED. Second explanation landed same day: the 96 km/wk bike commute was unlogged, so ~2400 'maintenance' was never maintenance. CORRECTED: uni days (Mon-Thu) 2650-2700, non-uni 2400, Sun long 2700, protein 155-165. Fuel today 2566 = ~100 under, noise. Protein 169. Creatine Y. Alcohol 0. Steps 9100. Bike 24 km.
A37: 46273 | B37: =IF(A37="","",IFERROR(INT((A37-DATE(2026,4,27))/7)+1,"")) | C37: 75.2 | D37: 7 | I37: RHR 46 (-1). Mot 10/En 8/Str 2. DOMS quad2 ham2 glute2 calf2 - first 4-way, bike flag tripped. Shin clean #18.
A38: 46274 | B38: =IF(A38="","",IFERROR(INT((A38-DATE(2026,4,27))/7)+1,"")) | C38: 75.2 | D38: 7.5 | I38: Wk B Wed - Cali Full Body #3 (14:10-15:00, 50 min, 28/28 sets, 293 reps, avg set RPE 7.0). AM CLEANEST OF THE BLOCK: sleep 7:30 q8 (bed 22:30 wake 06:35), RHR 46 delta -1, motivation 10, energy 10, stress 3, joints clear, ZERO DOMS above 1 anywhere (chest/back/shldr/arm all 0; quad/ham/glute/calf all 1). SHIN CLEAN check #20 (AM) and #21 (post-session). BIKE TRIGGER DID NOT FIRE, AND IT WAS ANSWERED UNMITIGATED: Tuesday's first-of-block 4-way leg DOMS 2 cleared to 1 across all four groups in 24 h while the full 24 km commute was ridden AND a 6 k run was run. The 9/8 read was right - local fatigue, not accumulation. Bike stays 24 km on uni days; Wed cali ran in full, BSS + SL-RDL NOT cut. Trigger disarmed for Wk B, re-arms on any future two consecutive mornings at >=2. Shoulders 3 -> 1 -> 0 in three days off cali = the 9/7 Mon->Wed swap fully vindicated, pressing landed on recovered delts. BW 75.20 second flat day off the -0.65 drop = noise, not a plateau; no kcal change (uni day 2650-2700). Protein: pull to ~160 after three straight high days (227 -> 169 -> 178). PM DATA NOT RECOVERABLE (confirmed 9/11): kcal, protein, Bike km and steps for 9/9 do not exist. Uni day so the bike was 24 km by routine, but it is NOT logged as measured. Not chased, not reconstructed - an invented number is worse than a gap. Wk B fuel/bike compliance is therefore a 5-day week, not 7.
A39: 46275 | B39: =IF(A39="","",IFERROR(INT((A39-DATE(2026,4,27))/7)+1,"")) | I39: Wk B Thu - REST (full), as prescribed. The rest day created by the 9/7 double-swap (cali #3 Mon->Wed, cali #4 Fri->Sat, Monday's rest spent on the week's shortest run). ZERO runs missed - the revised week never had a Thursday run. Uni day, bike 24 km by routine but unmeasured. AM + PM BLOCKS NOT RECOVERABLE (confirmed by user 9/11): no sleep, BW, RHR, DOMS, shin check, kcal, protein, bike km or steps exist for this day. A full dark day of data on a rest day. NOT reconstructed. Two consequences: (1) the BW series has a hole between 75.20 (9/9) and 76.20 (9/11), so the +1.00 kg jump is measured across 48 h, not 24 - which makes the water/glycogen read MORE likely, not less; (2) the shin-check count loses a day - Thu took none, so Fri 9/11 AM is check #22, not #23. Numbering corrected downstream; the clean streak itself is unbroken, the count is simply one lower than previously stated. Countermeasure is the one this block already named: two-touch logging ON the day.
A40: 46276 | B40: =IF(A40="","",IFERROR(INT((A40-DATE(2026,4,27))/7)+1,"")) | C40: 76.2 | D40: 10 | I40: Wk B Fri - run easy 6 k PM (cali #4 sits Sat after the 9/7 swap). AM: sleep 10:00 q10 = longest sleep in the log, RHR 45 (delta +1 vs 7 d, baseline 44, trending down off 46), motivation 10, energy 10, stress 3, tendons clean. SHIN CLEAN check #22 (renumbered: Thu 9/10 took no check). DOMS chest 2 / back 2 / shldr 2 / arm 1 = 48 h off cali #3, the first session carrying the B2 second push-up block, so a mild press+pull bump is the seed working. Zero impact on a run; Sat cali #4 lands at 72 h, clear, no cuts owed. LEGS 1/1/1/1 for the SECOND consecutive morning -> bike trigger stays DISARMED (needs two consecutive mornings at >=2). Bike holds 24 km on uni days; Friday is bike-free regardless. BW 76.20 = +1.00 kg off two flat days at 75.20, and measured across 48 h because 9/10 was not logged. NOT FAT: +1 kg of fat needs +7700 kcal against days that ran ~2400-2700. Water/glycogen/sodium. The block already ran this exact experiment - 75.85 held flat three days under a +937 kcal day, then dropped 0.65 overnight. Same noise band, same answer. NO KCAL CHANGE. 7-day picture 75.85/75.85/75.85/75.20/75.20/(hole)/76.20 = avg 75.69, still inside the 8/31 close +1. MON 9/14 AM MAKES THE TREND CALL, not today. Non-uni day -> ~2400 kcal, protein pull to ~160 (227 -> 169 -> 178 run must stop). Cleanest readiness of the week; nothing to autoregulate, run goes full 6 k. Rules: open ~7:50/km, avg HR 140-145, HARD ceiling 150, metronome 166 matched by SHORTENING STRIDE. This run is Sunday's rehearsal - Tue's 8:01/km produced cadence 163 and the 12 k opens at exactly this pace.
A41: 46277 | B41: =IF(A41="","",IFERROR(INT((A41-DATE(2026,4,27))/7)+1,"")) | I41: Wk B Sat - CALI #4 MISSED, ILLNESS. User sick Sat + Sun, reported 9/13. No AM block, no PM block, no session, no shin check. NOT reconstructed - missing data is written off, never back-filled from memory; an invented number is worse than an honest gap. WHAT WAS LOST: the second cali day of Wk B, which would have carried the first bumps off the 9/9 gate clears - tibialis to SLOW-ECCENTRIC 3x20 and side plank to 2x45 s/side, with A1 push-up holding all four sets at setting 3. Those advancements are UNRUN, not cancelled: they carry forward intact to the next cali session, gates stay cleared, nothing regresses on one missed session. Cali frequency for Wk B closes at 1 of 2. NO MAKE-UP SESSION - stacking cali into a re-entry week would put loaded legs in front of the first post-illness run, which is backwards: the run is the session that matters and the bone is the gate.
A42: 46278 | B42: =IF(A42="","",IFERROR(INT((A42-DATE(2026,4,27))/7)+1,"")) | I42: Wk B Sun - LONG 12 k MISSED, ILLNESS, second consecutive day. User reported 16:13: still symptomatic but IMPROVING vs Saturday. No AM block, no PM block, no BW, no shin check. NOT reconstructed. THE LONG IS GONE AND IS NOT CHASED - not moved to Monday, not compressed into next week. Reported at 16:13 and the long is an AM session by design; two sick days sat in front of it; a 12 k off illness on bone only 5 weeks past a 34-day layoff spends the tibia budget for nothing. 'Better than yesterday' is not 'clear'. SICK RULE - NECK CHECK: above neck only (nose/throat/sneeze) = easy run permitted at reduced distance, HR ceiling 140. Below neck (fever/chest/body aches/GI) = ZERO training until 24 h FULLY symptom-free, then one easy short run before anything loaded. Fever is a hard stop; myocarditis risk is not traded for a session. WK B FINAL: runs 3 of 4, 17 of 29 km, cali 1 of 2, 2 rest as planned + 2 lost. First missed sessions of Block 2. THIS IS ILLNESS, NOT DRIFT - categorically different from the Jul 29 - Aug 30 dark month and not treated the same way. Two days do not move the block; panic-compressing them would. BW TREND CALL VOID: 76.20 (9/11) is confounded by the 9/10 data hole plus two illness days (appetite, hydration, glycogen swing). Mon 9/14 AM reads nothing useful. Next real BW call ~9/17. No kcal change made on illness data. FRI SEP 18 BENCHMARK AT RISK - the decision Wk C turns on. The 8 k benchmark gates the whole goal-pace addendum (sub-3:00 vs sub-3:10; the 3 k @ 6:20 inside the Sep 27 long). A benchmark on a post-illness engine reads falsely slow and would retire the stretch goal for the wrong reason. The benchmark is moveable; the bone is not. Call made off the first clean AM, not before. WK C DEFERRED to the first symptom-free morning. Re-entry shape: one easy short run first, HR ceiling 140, distance set by bone - not a jump back onto the ramp where it was interrupted.
A43: 46279 | B43: =IF(A43="","",IFERROR(INT((A43-DATE(2026,4,27))/7)+1,"")) | I43: Wk B/C gap Mon - REST, ILLNESS day 3. No run, no cali, no AM block, no PM block, no BW, no shin check. NOT reconstructed. Uni day, bike commute ridden but unmeasured - not logged as a number. MONDAY AM CALI SLOT LOST and NOT made up: stacking a cali session into a re-entry week would put loaded legs in front of the first post-illness run, which is backwards - the run is the session that matters and the bone is the gate. BW TREND CALL THAT WAS SCHEDULED FOR TODAY IS VOID: no weigh-in taken, and 9/11's 76.20 is already confounded by the 9/10 data hole plus illness (appetite, hydration, glycogen). First honest BW reading is Thu 9/17; trend call Sun 9/20. NO KCAL CHANGE ON ILLNESS DATA.
A44: 46280 | B44: =IF(A44="","",IFERROR(INT((A44-DATE(2026,4,27))/7)+1,"")) | I44: Wk C eve Tue - REST, illness clearing. SYMPTOM-FREE FROM THIS MORNING ONLY = under 24 h, so the neck-check gate is NOT met and there is NO re-entry run today. Below-neck rule governs: zero training until 24 h FULLY symptom-free, then ONE easy short run before anything loaded. 'Better than yesterday' is not 'clear'. Uni day, bike commute ridden, nothing else. WED 9/16 AM IS THE 24 H MARK. Run gap now 5 days (last run Fri 9/11, 6 k). THIS IS ILLNESS, NOT DRIFT - no make-ups, no clawed-back km, repeat don't compress. WK C SET TONIGHT: 21 km / 3 runs / 1 cali / 2 rest - Wed 4 k re-entry HR CEILING 140 (gated on a still-clear Wed AM), Thu REST, Fri cali #4 + 5 k, Sat REST, Sun LONG 12 k (reuses Wk B's lost long rather than jumping to where the ramp stopped). FRI SEP 18 8 K BENCHMARK DEFERRED TO FRI SEP 25: an 8 k all-out off two sick days and a 5-day run gap reads falsely slow and would retire sub-3:00 for the wrong reason - the benchmark is moveable, the bone is not. Sep 25 still sits 2 days before the Sep 27 long so the goal-pace addendum survives intact; gate thresholds unchanged. Consequence: NOTHING ABOVE HR 150 THROUGH FRI SEP 25 - Wk C is 100% easy. DECISION DUE SUN 9/20: the 12->18->22 long-run ramp is +50% in one week on bone that will have run 21 km in three weeks; recommendation is 16 k on 9/27 and 20 k on 10/4, decided off the 9/20 shin check and back-half pace.
A45: 46281 | B45: =IF(A45="","",IFERROR(INT((A45-DATE(2026,4,27))/7)+1,"")) | I45: Wk C Wed - RUN RE-ENTRY 4 k PM. AM BLOCK NOT SUPPLIED - no BW, no sleep, no RHR, no DOMS. NOT reconstructed. Wednesday AM was the 24 h symptom-free gate; the run went ahead, so the gate is recorded as passed by the athlete's own call, zero illness symptoms reported. See Running Log 9/16 for the session and its three rule breaches. Shin CLEAN check #24 (same-night, so not yet the bone verdict). First honest post-illness BW was scheduled for Thu 9/17 and was NOT taken - BW trend remains VOID since 9/11's confounded 76.20; no kcal change made on illness data.
A46: 46282 | B46: =IF(A46="","",IFERROR(INT((A46-DATE(2026,4,27))/7)+1,"")) | I46: Wk C Thu - REST, FULL. Prescribed rest + 24 km strict-Z1 bike commute; athlete took full rest, BIKE 0 km, unprompted. CORRECT CALL: 9/16 ran 19 bpm over ceiling at 6:14/km on 5-day-detrained legs PLUS a doubled 24 km bike. Dropping today's 24 km is exactly the right lever - the bike is the load to spend when legs and recovery collide because it carries ZERO bone value. Net across the two days: 36 km bike prescribed, 24 km ridden - budget balanced, not overspent. SHIN CLEAN check #25 - THIS IS THE ONE THAT COUNTS: the 24 h read on 9/16's 6:14/km. Same-night checks miss bone stress, 24-72 h does not. Highest per-strike impact of the block landed on 5-day-detrained legs and the tibia took it. 25/25 clean this block. Fri 9/18 AM closes the 72 h window. Feels fine generally, no illness symptoms. Creatine Y. KCAL/PROTEIN NOT COUNTED - written off. USER DIRECTIVE 2026-09-17: do not re-ask for macro numbers; one ask max, then written off silently. No BW taken -> BW trend call still VOID, next opportunity Sun 9/20. Consequence: Fri 9/18 lands on a genuinely clean 48 h - cali #4 + 5 k run both go as written, no cuts owed, HR ceiling 145.
A47: 46286 | B47: =IF(A47="","",IFERROR(INT((A47-DATE(2026,4,27))/7)+1,"")) | I47: Wk D Mon - run easy 6 k AM, DONE (see Running Log 9/21). AM BLOCK NOT SUPPLIED - no BW, no sleep, no RHR, no DOMS, no motivation/energy/stress. NOT reconstructed. Shin CLEAN check #26 reported with the run. BW TREND STILL VOID: the last weigh-in is 9/11's confounded 76.20, and 9/14, 9/17 and 9/20 were all missed - the series now has a 10-day hole and no kcal decision can be made off it. NEXT REAL BW CALL NEEDS A CLEAN AM WEIGH-IN; earliest useful trend read is a week of consecutive mornings. Macros not counted - written off, not re-asked (user directive 2026-09-17). Creatine Y. Bike 0 km on a uni day -> fuel target for the day is ~2400, not 2650-2700.
A48: 46287 | B48: =IF(A48="","",IFERROR(INT((A48-DATE(2026,4,27))/7)+1,"")) | I48: Wk D Tue - Cali #5 full, DONE (see Lifting Log 9/22). AM BLOCK NOT SUPPLIED - no BW; series dark since 9/11 (11 days). Shin CLEAN #27. Bike 24 km (uni day). Kcal 2772 (target 2650-2700, +72). Protein 161 g on target. Creatine Y. Pain none.
A49: 46288 | B49: =IF(A49="","",IFERROR(INT((A49-DATE(2026,4,27))/7)+1,"")) | C49: 76.4 | D49: 8 | I49: Wk D Wed - REST, FULL. AM: sleep 8 h (02:00-10:00) q8, RHR 46 (-2), mot 10/energy 10/stress 2, DOMS back/shldr/arm 3 (9/22 RPE-10 sets + compressed rests), legs 1, shin CLEAN #28. BW 76.40 = first reading in 12 days, single point, NO kcal change. SUN 9/20 LONG MISSED (user 9/23) -> Sun 9/27 cut to 13 k (10 easy + 3 @ 6:20), Wk D 35 -> 33 km; Wk E peak long 20 k off (~16-17 k, decide off 9/27 shin). PM: bike 0 (uni day -> target ~2400), kcal 2933 (+530), protein 169, creatine Y.
A50: 46289 | B50: =IF(A50="","",IFERROR(INT((A50-DATE(2026,4,27))/7)+1,"")) | C50: 77.05 | D50: 8.75 | I50: Wk D Thu - Run easy 4 k (see Running Log 9/24). AM: sleep 8:45 (23:45-08:30) q8, RHR 45 (-2), mot 10/energy 10/stress 2, DOMS chest/back/shldr/arm 3 (48 h peak of 9/22 RPE-10 sets), quad/ham 2, glute/calf 1, shin CLEAN #29. BW 77.05 (+0.65 d/d) - 2nd reading, NO kcal change, trend call Sun 9/27 on >=3. PM: bike 0 (uni day -> ~2400), kcal 2596 (+196), protein 175 (+10 over 155-165), creatine Y, alcohol 0, steps 9891, shin CLEAN #30.
A51: 46290 | B51: =IF(A51="","",IFERROR(INT((A51-DATE(2026,4,27))/7)+1,"")) | C51: 77.05 | D51: 8.5 | I51: Wk D Fri - 8 K BENCHMARK (see Running Log 9/25). AM: sleep 8:30 (00:30-09:00) q10, RHR 46 (-1), mot 10/energy 10/stress 1, DOMS chest 1 / back 2 / shldr 2 / arm 2, quad 1 / ham 1 / glute 0 / calf 0, shin CLEAN #31. BW 77.05 flat d/d (3rd reading), NO kcal change, trend call Sun 9/27. Cali #6 moved to Sat 9/26 AM. PM: bike 0, kcal 2706 (+306, 3rd day over; 684 kcal benchmark), protein 178, creatine Y, alcohol 0, steps 14538, shin CLEAN #32, RPE 9.
A52: 46291 | B52: =IF(A52="","",IFERROR(INT((A52-DATE(2026,4,27))/7)+1,"")) | C52: 76.7 | D52: 9.25 | I52: Wk D Sat - CALI #6 UPPER ONLY (see Lifting Log 9/26). AM: sleep 9:15 (23:45-09:00) q10, RHR 45 (-1), mot 10/energy 10/stress 2, DOMS chest 0 / back 1 / shldr 1 / arm 1, quad/ham/glute/calf 2 (benchmark hangover), shin CLEAN #33. BW 76.70 (-0.35 d/d), 4th reading, trend call Sun 9/27. PM: 22/22 sets 55 min avg RPE 7.6, 0 RPE-10 sets, row cap held, bike 0, kcal 2485 (+85), protein 171, creatine Y, shin CLEAN #34.
...

Sheet Personal Records
A1: Exercise | B1: Best Weight (kg) | C1: Best Reps @ Weight | D1: Date Achieved | E1: Best e1RM (kg) | F1: Best Single-Set Volume
A2: Bench Press | B2: =IF(COUNTIF('Lifting Log'!D:D,A2)=0,"",SUMPRODUCT(MAX(('Lifting Log'!D2:D801=A2)*'Lifting Log'!G2:G801))) | C2: =IF(COUNTIF('Lifting Log'!D:D,A2)=0,"",SUMPRODUCT(MAX(('Lifting Log'!D2:D801=A2)*('Lifting Log'!G2:G801=B2)*'Lifting Log'!F2:F801))) | D2: =IF(COUNTIF('Lifting Log'!D:D,A2)=0,"",SUMPRODUCT(MAX(('Lifting Log'!D2:D801=A2)*('Lifting Log'!G2:G801=B2)*'Lifting Log'!A2:A801))) | E2: =IF(COUNTIF('Lifting Log'!D:D,A2)=0,"",SUMPRODUCT(MAX(('Lifting Log'!D2:D801=A2)*IFERROR('Lifting Log'!J2:J801*1,0)))) | F2: =IF(COUNTIF('Lifting Log'!D:D,A2)=0,"",SUMPRODUCT(MAX(('Lifting Log'!D2:D801=A2)*IFERROR('Lifting Log'!I2:I801*1,0))))
A3: Barbell Row | B3: =IF(COUNTIF('Lifting Log'!D:D,A3)=0,"",SUMPRODUCT(MAX(('Lifting Log'!D2:D801=A3)*'Lifting Log'!G2:G801))) | C3: =IF(COUNTIF('Lifting Log'!D:D,A3)=0,"",SUMPRODUCT(MAX(('Lifting Log'!D2:D801=A3)*('Lifting Log'!G2:G801=B3)*'Lifting Log'!F2:F801))) | D3: =IF(COUNTIF('Lifting Log'!D:D,A3)=0,"",SUMPRODUCT(MAX(('Lifting Log'!D2:D801=A3)*('Lifting Log'!G2:G801=B3)*'Lifting Log'!A2:A801))) | E3: =IF(COUNTIF('Lifting Log'!D:D,A3)=0,"",SUMPRODUCT(MAX(('Lifting Log'!D2:D801=A3)*IFERROR('Lifting Log'!J2:J801*1,0)))) | F3: =IF(COUNTIF('Lifting Log'!D:D,A3)=0,"",SUMPRODUCT(MAX(('Lifting Log'!D2:D801=A3)*IFERROR('Lifting Log'!I2:I801*1,0))))
A4: Incline DB Press | B4: =IF(COUNTIF('Lifting Log'!D:D,A4)=0,"",SUMPRODUCT(MAX(('Lifting Log'!D2:D801=A4)*'Lifting Log'!G2:G801))) | C4: =IF(COUNTIF('Lifting Log'!D:D,A4)=0,"",SUMPRODUCT(MAX(('Lifting Log'!D2:D801=A4)*('Lifting Log'!G2:G801=B4)*'Lifting Log'!F2:F801))) | D4: =IF(COUNTIF('Lifting Log'!D:D,A4)=0,"",SUMPRODUCT(MAX(('Lifting Log'!D2:D801=A4)*('Lifting Log'!G2:G801=B4)*'Lifting Log'!A2:A801))) | E4: =IF(COUNTIF('Lifting Log'!D:D,A4)=0,"",SUMPRODUCT(MAX(('Lifting Log'!D2:D801=A4)*IFERROR('Lifting Log'!J2:J801*1,0)))) | F4: =IF(COUNTIF('Lifting Log'!D:D,A4)=0,"",SUMPRODUCT(MAX(('Lifting Log'!D2:D801=A4)*IFERROR('Lifting Log'!I2:I801*1,0))))
